{ 
   "registryname":"sifting_machine_basic",
   "localizedname":"Basic Industrial Sifter",
   "requires-blueprint":true,
   "color":"B1B1B1",
   "parts":[ 
      { 
         "x":-1,
         "y":0,
         "z":1,
         "elements":[ 
            "contenttweaker:chassissteel@0",
            "modularmachinery:blockfluidinputhatch"
         ]
      },
      { 
         "x":-2,
         "y":0,
         "z":2,
         "elements":[ 
            "modularmachinery:blockenergyinputhatch"
         ]
      },
      { 
         "x":0,
         "y":2,
         "z":2,
         "elements":[ 
            "modularmachinery:blockinputbus"
         ]
      },
      { 
         "x":0,
         "y":0,
         "z":1,
         "elements":[ 
            "contenttweaker:chassissteel@0",
            "modularmachinery:blockfluidinputhatch"
         ]
      },
      { 
         "x":-1,
         "y":0,
         "z":2,
         "elements":[ 
            "contenttweaker:chassissteel@0",
            "modularmachinery:blockfluidinputhatch"
         ]
      },
      { 
         "x":-2,
         "y":0,
         "z":3,
         "elements":[ 
            "contenttweaker:motorsteel@0"
         ]
      },
      { 
         "x":1,
         "y":0,
         "z":1,
         "elements":[ 
            "contenttweaker:chassissteel@0",
            "modularmachinery:blockfluidinputhatch"
         ]
      },
      { 
         "x":-1,
         "y":0,
         "z":3,
         "elements":[ 
            "immersiveengineering:metal_decoration0@5"
         ]
      },
      { 
         "x":0,
         "y":0,
         "z":3,
         "elements":[ 
            "contenttweaker:chassissteel@0",
            "modularmachinery:blockfluidinputhatch"
         ]
      },
      { 
         "x":1,
         "y":0,
         "z":2,
         "elements":[ 
            "contenttweaker:chassissteel@0",
            "modularmachinery:blockfluidinputhatch"
         ]
      },
      { 
         "x":1,
         "y":0,
         "z":3,
         "elements":[ 
            "immersiveengineering:metal_decoration0@5"
         ]
      },
      { 
         "x":0,
         "y":-1,
         "z":0,
         "elements":[ 
            "modularmachinery:blockoutputbus"
         ]
      },
      { 
         "x":-1,
         "y":1,
         "z":1,
         "elements":[ 
            "minecraft:planks@0"
         ]
      },
      { 
         "x":0,
         "y":1,
         "z":1,
         "elements":[ 
            "minecraft:planks@0"
         ]
      },
      { 
         "x":-1,
         "y":1,
         "z":2,
         "elements":[ 
            "minecraft:planks@0"
         ]
      },
      { 
         "x":0,
         "y":1,
         "z":2,
         "elements":[ 
            "minecraft:planks@0"
         ]
      },
      { 
         "x":1,
         "y":1,
         "z":1,
         "elements":[ 
            "minecraft:planks@0"
         ]
      },
      { 
         "x":-1,
         "y":-1,
         "z":1,
         "elements":[ 
            "minecraft:planks@0"
         ]
      },
      { 
         "x":-1,
         "y":1,
         "z":3,
         "elements":[ 
            "minecraft:planks@0"
         ]
      },
      { 
         "x":0,
         "y":1,
         "z":3,
         "elements":[ 
            "minecraft:planks@0"
         ]
      },
      { 
         "x":1,
         "y":1,
         "z":2,
         "elements":[ 
            "minecraft:planks@0"
         ]
      },
      { 
         "x":0,
         "y":-1,
         "z":1,
         "elements":[ 
            "minecraft:planks@0"
         ]
      },
      { 
         "x":-1,
         "y":-1,
         "z":2,
         "elements":[ 
            "minecraft:planks@0"
         ]
      },
      { 
         "x":1,
         "y":1,
         "z":3,
         "elements":[ 
            "minecraft:planks@0"
         ]
      },
      { 
         "x":0,
         "y":-1,
         "z":2,
         "elements":[ 
            "minecraft:planks@0"
         ]
      },
      { 
         "x":1,
         "y":-1,
         "z":1,
         "elements":[ 
            "minecraft:planks@0"
         ]
      },
      { 
         "x":-1,
         "y":-1,
         "z":3,
         "elements":[ 
            "minecraft:planks@0"
         ]
      },
      { 
         "x":1,
         "y":-1,
         "z":2,
         "elements":[ 
            "minecraft:planks@0"
         ]
      },
      { 
         "x":0,
         "y":-1,
         "z":3,
         "elements":[ 
            "minecraft:planks@0"
         ]
      },
      { 
         "x":1,
         "y":-1,
         "z":3,
         "elements":[ 
            "minecraft:planks@0"
         ]
      }
   ]
}